Workbook

Sheet 3 Statement Model
A1: $ In millions
B2: Apple INC
B3: APPL
B4: 3 Statement Financial Summary
B8: Income Statement | C8: 2023 | D8: =C8+1 -> 2024 | E8: =D8+1 -> 2025 | F8: =E8+1 -> 2026 | G8: =F8+1 -> 2027 | H8: =G8+1 -> 2028 | I8: =H8+1 -> 2029 | J8: =I8+1 -> 2030
A9: x | B9: Net Sales (Revenue) | C9: 383285 | D9: 391035 | E9: 416161 | F9: =E9*(1+F28) -> 449453.88 | G9: =F9*(1+G28) -> 485410.19 | H9: =G9*(1+H28) -> 524243.01 | I9: =H9*(1+I28) -> 566182.45 | J9: =I9*(1+J28) -> 611477.04
B10: COGS | C10: -214137 | D10: -210352 | E10: -220960 | F10: =-F9*(1-F29) -> -240457.83 | G10: =-G9*(1-G29) -> -259694.45 | H10: =-H9*(1-H29) -> -280470.01 | I10: =-I9*(1-I29) -> -302907.61 | J10: =-J9*(1-J29) -> -327140.22
B11: Gross Profit | C11: =C9+C10 -> 169148 | D11: =D9+D10 -> 180683 | E11: =E9+E10 -> 195201 | F11: =F9+F10 -> 208996.05 | G11: =G9+G10 -> 225715.74 | H11: =H9+H10 -> 243773 | I11: =I9+I10 -> 263274.84 | J11: =J9+J10 -> 284336.82
B12: R&D | C12: -29915 | D12: -31370 | E12: -34550 | F12: =-F9*F30 -> -35956.31 | G12: =-G9*G30 -> -38832.815 | H12: =-H9*H30 -> -41939.44 | I12: =-I9*I30 -> -45294.596 | J12: =-J9*J30 -> -48918.163
B13: SG&A | C13: -24392 | D13: -26097 | E13: -27601 | F13: =-F9*F31 -> -29214.502 | G13: =-G9*G31 -> -31551.662 | H13: =-H9*H31 -> -34075.795 | I13: =-I9*I31 -> -36801.859 | J13: =-J9*J31 -> -39746.008
B14: Operating Income | C14: =C11+C12+C13 -> 114841 | D14: =D11+D12+D13 -> 123216 | E14: =E11+E12+E13 -> 133050 | F14: =F11+F12+F13 -> 143825.24 | G14: =G11+G12+G13 -> 155331.26 | H14: =H11+H12+H13 -> 167757.76 | I14: =I11+I12+I13 -> 181178.38 | J14: =J11+J12+J13 -> 195672.65
B15: Other Income/Expense, Net | C15: -565 | D15: 269 | E15: -321 | F15: 0 | G15: 0 | H15: 0 | I15: 0 | J15: 0
B16: Provision for Income Taxes | C16: -16741 | D16: -29749 | E16: -20719 | F16: =-F14*F32 -> -22292.912 | G16: =-G14*G32 -> -24076.345 | H16: =-H14*H32 -> -26002.453 | I16: =-I14*I32 -> -28082.649 | J16: =-J14*J32 -> -30329.261
B17: Net Income | C17: =C14+C15+C16 -> 97535 | D17: =D14+D15+D16 -> 93736 | E17: =E14+E15+E16 -> 112010 | F17: =F14+F15+F16 -> 121532.33 | G17: =G14+G15+G16 -> 131254.92 | H17: =H14+H15+H16 -> 141755.31 | I17: =I14+I15+I16 -> 153095.73 | J17: =J14+J15+J16 -> 165343.39
B19: Historical Drivers
B21: Revenue Growth % | D21: =D9/C9 -1 -> 0.020219941 | E21: =E9/D9 -1 -> 0.064255118
B22: Gross Margin % | C22: =(C11/C9) -> 0.4413113 | D22: =(D11/D9) -> 0.4620635 | E22: =(E11/E9) -> 0.46905164
B23: R&D as a % of Revenue | C23: =-(C12/C9) -> 0.078048971 | D23: =-(D12/D9) -> 0.080222998 | E23: =-(E12/E9) -> 0.083020754
B24: SG&A as a % of Revenue | C24: =-(C13/C9) -> 0.063639328 | D24: =-(D13/D9) -> 0.066738272 | E24: =-(E13/E9) -> 0.066322889
A26: x
B27: Growth Assumptions
B28: Revenue Growth % | F28: 0.08 | G28: 0.08 | H28: 0.08 | I28: 0.08 | J28: 0.08
B29: Gross Margin % | F29: 0.465 | G29: 0.465 | H29: 0.465 | I29: 0.465 | J29: 0.465
B30: R&D as a % of Revenue | F30: 0.08 | G30: 0.08 | H30: 0.08 | I30: 0.08 | J30: 0.08
B31: SG&A as a % of Revenue | F31: 0.065 | G31: 0.065 | H31: 0.065 | I31: 0.065 | J31: 0.065
B32: Tax Rate | F32: 0.155 | G32: 0.155 | H32: 0.155 | I32: 0.155 | J32: 0.155
B33: Days Sales Outstanding | F33: 30 | G33: 30 | H33: 30 | I33: 30 | J33: 30
B34: Days Inventory Outstanding | F34: 11 | G34: 11 | H34: 11 | I34: 11 | J34: 11
B35: Days Payable Outstanding | F35: 105 | G35: 105 | H35: 105 | I35: 105 | J35: 105
A36: x | B36: CAPEX | F36: 0.03 | G36: 0.03 | H36: 0.03 | I36: 0.03 | J36: 0.03
B37: Cash Dividends | F37: 15000 | G37: 15000 | H37: 15000 | I37: 15000 | J37: 15000
B38: Depreciation as a % | F38: 0.17 | G38: 0.17 | H38: 0.17 | I38: 0.17 | J38: 0.17
B39: Diluted Shares Outstanding | D39: 15408 | E39: 15005 | F39: =E39*(1-0.02) -> 14704.9 | G39: =F39*(1-0.02) -> 14410.802 | H39: =G39*(1-0.02) -> 14122.586 | I39: =H39*(1-0.02) -> 13840.134 | J39: =I39*(1-0.02) -> 13563.332
B42: Balance Sheet
B43: Cash and Equivalents | D43: 29943 | E43: 35934 | F43: =F112 -> 63200.536 | G43: =G112 -> 101342.05 | H43: =H112 -> 149869.42 | I43: =I112 -> 209588.93 | J43: =J112 -> 281375.53
B44: Marketable Securities | D44: 35228 | E44: 18763 | F44: 18763 | G44: 18763 | H44: 18763 | I44: 18763 | J44: 18763
B45: Accounts Receivable | D45: 33410 | E45: 39777 | F45: =(F33/365)*F9 -> 36941.415 | G45: =(G33/365)*G9 -> 39896.728 | H45: =(H33/365)*H9 -> 43088.466 | I45: =(I33/365)*I9 -> 46535.544 | J45: =(J33/365)*J9 -> 50258.387
B46: Vendor Non-trade Receivables | D46: 32833 | E46: 33180 | F46: 33180 | G46: 33180 | H46: 33180 | I46: 33180 | J46: 33180
B47: Inventories | D47: 7286 | E47: 5718 | F47: =(F34/365)*-F10 -> 7246.6742 | G47: =(G34/365)*-G10 -> 7826.4081 | H47: =(H34/365)*-H10 -> 8452.5208 | I47: =(I34/365)*-I10 -> 9128.7225 | J47: =(J34/365)*-J10 -> 9859.0202
B48: Other Current Assets | D48: 14287 | E48: 14585 | F48: 14585 | G48: 14585 | H48: 14585 | I48: 14585 | J48: 14585
...

Sheet DCF Valuation
A2: x | B2: Apple DCF
B3: AAPL
B4: DCF Valuation | C4: Ticker: | D4: AAPL | F4: Implied Share Price | H4: =G33 -> 134.70156
B5: $ in millions | C5: Date: | D5: 46269 | F5: Today's Share price | H5: =WACC!C7 -> 319.97
B7: Assumptions
B8: % of OPEX | C8: 0.12 | D8: 0.12 | E8: 0.12 | F8: 0.12 | G8: 0.12
B9: WACC | C9: =WACC!$C$24 -> 0.10101505
B10: Terminal Growth Rate | C10: 0.035
C13: 1 | D13: 2 | E13: 3 | F13: 4 | G13: 5
B14: DCF | C14: 2026 | D14: =C14+1 -> 2027 | E14: =D14+1 -> 2028 | F14: =E14+1 -> 2029 | G14: =F14+1 -> 2030
B15: Revenue | C15: ='3 Statement Model'!F9 -> 449453.88 | D15: ='3 Statement Model'!G9 -> 485410.19 | E15: ='3 Statement Model'!H9 -> 524243.01 | F15: ='3 Statement Model'!I9 -> 566182.45 | G15: ='3 Statement Model'!J9 -> 611477.04
B16: EBIT | C16: ='3 Statement Model'!F14 -> 143825.24 | D16: ='3 Statement Model'!G14 -> 155331.26 | E16: ='3 Statement Model'!H14 -> 167757.76 | F16: ='3 Statement Model'!I14 -> 181178.38 | G16: ='3 Statement Model'!J14 -> 195672.65
B17: Taxes | C17: =-C16*'3 Statement Model'!F32 -> -22292.912 | D17: =-D16*'3 Statement Model'!G32 -> -24076.345 | E17: =-E16*'3 Statement Model'!H32 -> -26002.453 | F17: =-F16*'3 Statement Model'!I32 -> -28082.649 | G17: =-G16*'3 Statement Model'!J32 -> -30329.261
B18: NOPAT | C18: =C16+C17 -> 121532.33 | D18: =D16+D17 -> 131254.92 | E18: =E16+E17 -> 141755.31 | F18: =F16+F17 -> 153095.73 | G18: =G16+G17 -> 165343.39
B19: D&A | C19: ='3 Statement Model'!F79 -> 8471.78 | D19: ='3 Statement Model'!G79 -> 9323.7922 | E19: ='3 Statement Model'!H79 -> 10214.339 | F19: ='3 Statement Model'!I79 -> 11151.541 | G19: ='3 Statement Model'!J79 -> 12143.31
B20: CAPEX | C20: ='DCF Valuation'!C15*'3 Statement Model'!F36 -> 13483.616 | D20: ='DCF Valuation'!D15*'3 Statement Model'!G36 -> 14562.306 | E20: ='DCF Valuation'!E15*'3 Statement Model'!H36 -> 15727.29 | F20: ='DCF Valuation'!F15*'3 Statement Model'!I36 -> 16985.473 | G20: ='DCF Valuation'!G15*'3 Statement Model'!J36 -> 18344.311
B21: Change in NWC | C21: =('3 Statement Model'!F45+'3 Statement Model'!F47+'3 Statement Model'!F48-'3 Statement Model'!F56-'3 Statement Model'!F57)-('3 Statement Model'!E45+'3 Statement Model'!E47+'3 Statement Model'!E48-'3 Statement Model'!E56-'3 Statement Model'!E57) -> -619.71021 | D21: =('3 Statement Model'!G45+'3 Statement Model'!G47+'3 Statement Model'!G48-'3 Statement Model'!G56-'3 Statement Model'!G57)-('3 Statement Model'!F45+'3 Statement Model'!F47+'3 Statement Model'!F48-'3 Statement Model'!F56-'3 Statement Model'!F57) -> -1998.7768 | E21: =('3 Statement Model'!H45+'3 Statement Model'!H47+'3 Statement Model'!H48-'3 Statement Model'!H56-'3 Statement Model'!H57)-('3 Statement Model'!G45+'3 Statement Model'!G47+'3 Statement Model'!G48-'3 Statement Model'!G56-'3 Statement Model'!G57) -> -2158.679 | F21: =('3 Statement Model'!I45+'3 Statement Model'!I47+'3 Statement Model'!I48-'3 Statement Model'!I56-'3 Statement Model'!I57)-('3 Statement Model'!H45+'3 Statement Model'!H47+'3 Statement Model'!H48-'3 Statement Model'!H56-'3 Statement Model'!H57) -> -2331.3733 | G21: =('3 Statement Model'!J45+'3 Statement Model'!J47+'3 Statement Model'!J48-'3 Statement Model'!J56-'3 Statement Model'!J57)-('3 Statement Model'!I45+'3 Statement Model'!I47+'3 Statement Model'!I48-'3 Statement Model'!I56-'3 Statement Model'!I57) -> -2517.8831
B22: UFCF | C22: =C18+C19-C20-C21 -> 117140.2 | D22: =D18+D19-D20-D21 -> 128015.18 | E22: =E18+E19-E20-E21 -> 138401.04 | F22: =F18+F19-F20-F21 -> 149593.17 | G22: =G18+G19-G20-G21 -> 161660.27
B23: Present Value of FCF | C23: =C22/(1+$C$9)^C13 -> 106392.92 | D23: =D22/(1+$C$9)^D13 -> 105602.68 | E23: =E22/(1+$C$9)^E13 -> 103695.42 | F23: =F22/(1+$C$9)^F13 -> 101797.88 | G23: =G22/(1+$C$9)^G13 -> 99916.458
B26: Terminal Value | G26: =(G22*(1+C10))/(C9-C10) -> 2534549
A27: x | B27: Present Value of Terminal Value | G27: =G26/(1+C9)^G13 -> 1566514.5
B28: Enterprise Value | G28: =SUM(C23:G23,G27) -> 2083919.8
B29: Cash | G29: ='3 Statement Model'!E112 -> 35934
B30: Debt | G30: ='3 Statement Model'!E59+'3 Statement Model'!E60+'3 Statement Model'!E62 -> 98657
B31: Equity Value | G31: =G28+G29-G30 -> 2021196.8
B32: Shares | G32: ='3 Statement Model'!E39 -> 15005
B33: Share Price | G33: =G31/G32 -> 134.70156
B39: Sensitivity Table
B40: =G33 -> 134.70156 | C40: 0.08 | D40: 0.09 | E40: 0.095 | F40: 0.101 | G40: 0.11 | H40: 0.12
B41: 0.02 | C41: 156.9966 | D41: 133.38218 | E41: 123.94382 | F41: 114.16172 | G41: 101.9445 | H41: 90.961675
B42: 0.025 | C42: 168.99514 | D42: 141.76944 | E42: 131.08092 | F42: 120.11682 | G42: 106.58307 | H42: 94.565317
B43: 0.03 | C43: 183.39338 | D43: 151.55457 | E43: 139.31603 | F43: 126.91068 | G43: 111.80146 | H43: 98.569364
B44: 0.035 | C44: 200.99124 | D44: 163.11882 | E44: 148.92365 | F44: 134.7339 | G44: 117.71563 | H44: 103.04447
B45: 0.04 | C45: 222.98856 | D45: 176.99592 | E45: 160.27813 | F45: 143.83962 | G45: 124.47469 | H45: 108.07897

Sheet WACC
B2: WACC
A4: x | B4: WACC
B5: WACC = (% of Equity * Cost of Equity)+ (% of Debt * Cost of Debt*(1 - tax rate))
B6: Cost of Equity = Risk Free Rate * beta( expected return - Risk Free Rate)
B7: Current Apple stock (9/4/26) | C7: 319.97
B9: Debt | C9: ='3 Statement Model'!D59+'3 Statement Model'!D60+'3 Statement Model'!D62 -> 106629
B10: % Debt | C10: =C9/C22 -> 0.022160102
B11: Cost of Debt | C11: 0.042
B12: Tax Rate | C12: ='3 Statement Model'!F32 -> 0.155
B15: Equity Value | C15: =C7*'3 Statement Model'!F39 -> 4705126.9
B16: % Equity | C16: =C15/C22 -> 0.9778399
B17: Cost of Equity | C17: =C18+(C19*C20) -> 0.1025
B18: Risk Free Rate | C18: 0.048
B19: Beta | C19: 1.09
B20: Market Risk Premium | C20: 0.05
B22: Debt + Equity | C22: =C15+C9 -> 4811755.9
A24: x | B24: WACC | C24: =(C16*C17)+(C10*C11*(1-C12)) -> 0.10101505
